Workbook

Sheet Main
A1: Id | B1: Start time | C1: Completion time | D1: Email | E1: Name | F1: اسم المعلمة | G1: الأقسام الأكاديمية | H1: السنة الدراسية | I1: الشهر | J1: الفصل الدراسي | K1: الزائر | L1: Column1 | M1: استمارات للقيادة الوسطى | N1: عدد الزيارات | O1: اتساق تخطيط الدروس مع الكفايات التعليمية للمنهج ،ومراعاته احتياجات الطلبة | P1: توفير بيئة تعلم اَمنة ومحفزة خالية من المخاطر لضمان إنتاجية التعلم | Q1: تضمين الموقف التعليمي إرشادات وتوجيهات واضحة | R1: استثمار الوقت بما يحقق أهداف التعلم بصورة منتجة | S1: تحفيز الطلبة ورفع دافعيتهم بأساليب تمكنهم من المشاركة في التعلم وبناء شخصياتهم | T1: سلامة المادة العلمية ومراعاتها كفايات المنهج والمستويات المتوقعة للمرحلة التعليمية | U1: توظيف إستراتيجيات تعليم وتعلم فاعلة ،تسهم في دمج الطلبة على اختلاف احتياجاتهم | V1: توظيف التقويم والاستفادة من نتائجه في دعم جميع فئات المتعلمين وفق احتياجاتهم | W1: تنمية مهارات التفكير العليا للطلبة وتحدي قدراتهم | X1: توظيف التعليم التمايز لتلبية احتياجات الطلبة المتنوعة على اختلاف فئاتهم | Y1: توظيف المصادر والموارد التعليمية والتكنولوجية في عمليات التعليم والتعلم | Z1: تنمية مهارات الطلبة التكنولوجية ومهارات البحث والتعلم الذاتي ،وتشجيعهم على إنتاج المحتوى التعليمي الرقمي | AA1: إظهار الطلبة المعارف والمهارات الأساسية وفقاً لمرحلتهم التعليمية . | AB1: تحقيق الطلبة التقدم خلال الدروس ، واكتسابهم مهارات التعلم | AC1: التزام الطلبة بالقيم الإسلامية ،والوطنية ، والرقمية ،والاستعمال الاُمن للتكنولوجيا | AD1: التزام الطلبة السلوك الإيجابي نحو التعلم ،والانضباط الذاتي ،وتحمل المسؤوليات المختلفة | AE1: قدرة الطلبة على التواصل والمشاركة الفاعلة خلال تعلمهم | AF1: إظهار الطلبة الثقة بالنفس ،والقدرة على القيادة ، والمبادرة ،والابتكار | AG1: نجاحات المعلم | AH1: جوانب بحاجة إلى تطوير | AI1: أبرز نقاط القوة | AJ1: أبرز الجوانب التي تحتاج إلى تطوير | AK1: الدعم المقدم لها | AL1: توظيف جوانب التميز لديها | AM1: مدى التحسين في الأداء | AN1: 1اتساق تخطيط الدروس مع الكفايات التعليمية للمنهج ،ومراعاته احتياجات الطلبة | AO1: 2توفير بيئة تعلم اَمنة ومحفزة خالية من المخاطر لضمان إنتاجية التعلم | AP1: تضمين الموقف التعليمي إرشادات وتوجيهات واضحة1 | AQ1: استثمار الوقت بما يحقق أهداف التعلم بصورة منتجة1 | AR1: 5تحفيز الطلبة ورفع دافعيتهم بأساليب تمكنهم من المشاركة في التعلم وبناء شخصياتهم | AS1: سلامة المادة العلمية ومراعاتها كفايات المنهج والمستويات المتوقعة للمرحلة التعليمية1 | AT1: 7توظيف إستراتيجيات تعليم وتعلم فاعلة ،تسهم في دمج الطلبة على اختلاف احتياجاتهم | AU1: توظيف التقويم والاستفادة من نتائجه في دعم جميع فئات المتعلمين وفق احتياجاتهم1 | AV1: 9تنمية مهارات التفكير العليا للطلبة وتحدي قدراتهم | AW1: 10توظيف التعليم التمايز لتلبية احتياجات الطلبة المتنوعة على اختلاف فئاتهم | AX1: 11توظيف المصادر والموارد التعليمية والتكنولوجية في عمليات التعليم والتعلم | AY1: 12تنمية مهارات الطلبة التكنولوجية ومهارات البحث والتعلم الذاتي ،وتشجيعهم على إنتاج المحتوى التعليمي الرقمي | AZ1: 13إظهار الطلبة المعارف والمهارات الأساسية وفقاً لمرحلتهم التعليمية . | BA1: 14تحقيق الطلبة التقدم خلال الدروس ، واكتسابهم مهارات التعلم | BB1: التزام الطلبة بالقيم الإسلامية ،والوطنية ، والرقمية ،والاستعمال الاُمن للتكنولوجيا1 | BC1: 16التزام الطلبة السلوك الإيجابي نحو التعلم ،والانضباط الذاتي ،وتحمل المسؤوليات المختلفة | BD1: قدرة الطلبة على التواصل والمشاركة الفاعلة خلال تعلمهم1 | BE1: إظهار الطلبة الثقة بالنفس ،والقدرة على القيادة ، والمبادرة ،والابتكار1 | BF1: نقاط القوة في أدائي العام | BG1: نقاط الضعف التي تحتاج إلى تطوير | BH1: ما نوع الدعم الذي أحتاجه من زيارات القيادة الوسطى لجميع المعلمات لتطوير أدائي | BI1: مقترحاتي لتطوير أدائي في المواقف التعليمية | BJ1: 01اتساق تخطيط الدروس مع الكفايات التعليمية للمنهج ،ومراعاته احتياجات الطلبة | BK1: 02توفير بيئة تعلم اَمنة ومحفزة خالية من المخاطر لضمان إنتاجية التعلم | BL1: 03تضمين الموقف التعليمي إرشادات وتوجيهات واضحة | BM1: 04استثمار الوقت بما يحقق أهداف التعلم بصورة منتجة | BN1: 05تحفيز الطلبة ورفع دافعيتهم بأساليب تمكنهم من المشاركة في التعلم وبناء شخصياتهم | BO1: 06سلامة المادة العلمية ومراعاتها كفايات المنهج والمستويات المتوقعة للمرحلة التعليمية | BP1: 07توظيف إستراتيجيات تعليم وتعلم فاعلة ،تسهم في دمج الطلبة على اختلاف احتياجاتهم | BQ1: 08توظيف التقويم والاستفادة من نتائجه في دعم جميع فئات المتعلمين وفق احتياجاتهم | BR1: 09تنمية مهارات التفكير العليا للطلبة وتحدي قدراتهم | BS1: 010توظيف التعليم التمايز لتلبية احتياجات الطلبة المتنوعة على اختلاف فئاتهم | BT1: 011توظيف المصادر والموارد التعليمية والتكنولوجية في عمليات التعليم والتعلم | BU1: 012تنمية مهارات الطلبة التكنولوجية ومهارات البحث والتعلم الذاتي ،وتشجيعهم على إنتاج المحتوى التعليمي الرقمي | BV1: 013إظهار الطلبة المعارف والمهارات الأساسية وفقاً لمرحلتهم التعليمية . | BW1: 014تحقيق الطلبة التقدم خلال الدروس ، واكتسابهم مهارات التعلم | BX1: 015التزام الطلبة بالقيم الإسلامية ،والوطنية ، والرقمية ،والاستعمال الاُمن للتكنولوجيا | BY1: 016التزام الطلبة السلوك الإيجابي نحو التعلم ،والانضباط الذاتي ،وتحمل المسؤوليات المختلفة | BZ1: 017قدرة الطلبة على التواصل والمشاركة الفاعلة خلال تعلمهم | CA1: 018إظهار الطلبة الثقة بالنفس ،والقدرة على القيادة ، والمبادرة ،والابتكار | CB1: المعلم المزور | CC1: القسم الأكاديمي للمعلم المزور | CD1: اسم المدرسة (إذا كان/ت من مدرسة أخرى) | CE1: الأهداف التعليمية للحصة | CF1: أساليب واستراتيجيات التدريس الملحوظة | CG1: ما الذي يمكن أن أستفيد منه لتطوير ممارساتي التدريسية | CH1: أفكار جديدة يمكن أن أستفيد منه لتطوير ممارساتي التدريسية | CI1: توصيات المعلم المزور (خاص بالمعلم المزور) | CJ1: __PowerAppsId__ | CK1: الحكم العام | CL1: حكم للتقييم الذاتي
A2: 66 | B2: 45811.357 | C2: 45811.359 | D2: 890302057@moe.bh | E2: Afaf Hussain Ahmed Ebrahim Hussain Ahmed Ebrahim | F2: عفاف حسين أحمد | G2: قسم الحاسب الآلي | H2: 2024-2025 | J2: الفصل الدراسي الأول | K2: زيارات القيادة الوسطى لجميع المعلمات | M2: استمارة الزيارة الصفية | N2: الزيارة الأولى | O2: يتجاوز التوقعات بكثير | P2: يتجاوز التوقعات بكثير | Q2: يتجاوز التوقعات بكثير | R2: يتجاوز التوقعات بكثير | S2: يتجاوز التوقعات بكثير | T2: يتجاوز التوقعات بكثير | U2: يتجاوز التوقعات بكثير | V2: يتجاوز التوقعات بكثير | W2: يتجاوز التوقعات بكثير | X2: يتجاوز التوقعات بكثير | Y2: يتجاوز التوقعات بكثير | Z2: يتجاوز التوقعات بكثير | AA2: يتجاوز التوقعات بكثير | AB2: يتجاوز التوقعات بكثير | AC2: يتجاوز التوقعات بكثير | AD2: يتجاوز التوقعات بكثير | AE2: يتجاوز التوقعات بكثير | AF2: يتجاوز التوقعات بكثير | AG2: دعم جميع الطالبات حسب الفئات | AH2: - | CK2: =IF(AND(Main!AA2="يتجاوز التوقعات بكثير", Main!AB2="يتجاوز التوقعات بكثير"), "يتجاوز التوقعات بكثير", IF(OR(AND(Main!AA2="يتجاوز التوقعات بكثير", Main!AB2="يتجاوز التوقعات"), AND(Main!AA2="يتجاوز التوقعات", Main!AB2="يتجاوز التوقعات بكثير")), "يتجاوز التوقعات", IF(AND(Main!AA2="يتجاوز التوقعات", Main!AB2="يتجاوز التوقعات"), "يتجاوز التوقعات", IF(OR(AND(Main!AA2="يتجاوز التوقعات", Main!AB2="يفي بالتوقعات"), AND(Main!AA2="يفي بالتوقعات", Main!AB2="يتجاوز التوقعات")), "يفي بالتوقعات", IF(AND(Main!AA2="يفي بالتوقعات", Main!AB2="يفي بالتوقعات"), "يفي بالتوقعات", IF(OR(AND(Main!AA2="يفي بالتوقعات", Main!AB2="يفي بالتوقعات جزئياً"), AND(Main!AA2="يفي بالتوقعات جزئياً", Main!AB2="يفي بالتوقعات")), "يفي بالتوقعات جزئياً", IF(AND(Main!AA2="يفي بالتوقعات جزئياً", Main!AB2="يفي بالتوقعات جزئياً"), "يفي بالتوقعات جزئياً", "" ))))))) -> يتجاوز التوقعات بكثير | CL2: =IF(AND(Main!AZ2="يتجاوز التوقعات بكثير", Main!BA2="يتجاوز التوقعات بكثير"), "يتجاوز التوقعات بكثير", IF(OR(AND(Main!AZ2="يتجاوز التوقعات بكثير", Main!BA2="يتجاوز التوقعات"), AND(Main!AZ2="يتجاوز التوقعات", Main!BA2="يتجاوز التوقعات بكثير")), "يتجاوز التوقعات", IF(AND(Main!AZ2="يتجاوز التوقعات", Main!BA2="يتجاوز التوقعات"), "يتجاوز التوقعات", IF(OR(AND(Main!AZ2="يتجاوز التوقعات", Main!BA2="يفي بالتوقعات"), AND(Main!AZ2="يفي بالتوقعات", Main!BA2="يتجاوز التوقعات")), "يفي بالتوقعات", IF(AND(Main!AZ2="يفي بالتوقعات", Main!BA2="يفي بالتوقعات"), "يفي بالتوقعات", IF(OR(AND(Main!AZ2="يفي بالتوقعات", Main!BA2="يفي بالتوقعات جزئياً"), AND(Main!AZ2="يفي بالتوقعات جزئياً", Main!BA2="يفي بالتوقعات")), "يفي بالتوقعات جزئياً", IF(AND(Main!AZ2="يفي بالتوقعات جزئياً", Main!BA2="يفي بالتوقعات جزئياً"), "يفي بالتوقعات جزئياً", "" )))))))
A3: 67 | B3: 45811.359 | C3: 45811.361 | D3: 890302057@moe.bh | E3: Afaf Hussain Ahmed Ebrahim Hussain Ahmed Ebrahim | F3: عفاف حسين أحمد | G3: قسم الحاسب الآلي | H3: 2024-2025 | J3: الفصل الدراسي الأول | K3: زيارات القيادة الوسطى لجميع المعلمات | M3: استمارة الزيارة الصفية | N3: الزيارة الثانية | O3: يتجاوز التوقعات بكثير | P3: يتجاوز التوقعات بكثير | Q3: يتجاوز التوقعات بكثير | R3: يتجاوز التوقعات | S3: يتجاوز التوقعات بكثير | T3: يتجاوز التوقعات بكثير | U3: يتجاوز التوقعات بكثير | V3: يتجاوز التوقعات بكثير | W3: يتجاوز التوقعات | X3: يتجاوز التوقعات بكثير | Y3: يتجاوز التوقعات بكثير | Z3: يتجاوز التوقعات بكثير | AA3: يتجاوز التوقعات بكثير | AB3: يتجاوز التوقعات بكثير | AC3: يتجاوز التوقعات بكثير | AD3: يتجاوز التوقعات بكثير | AE3: يتجاوز التوقعات بكثير | AF3: يتجاوز التوقعات بكثير | AG3: ابتدعت في مراحل عرض الدرس وعرض انجازات الطالبات والاحتفاء بها | AH3: - | CK3: =IF(AND(Main!AA3="يتجاوز التوقعات بكثير", Main!AB3="يتجاوز التوقعات بكثير"), "يتجاوز التوقعات بكثير", IF(OR(AND(Main!AA3="يتجاوز التوقعات بكثير", Main!AB3="يتجاوز التوقعات"), AND(Main!AA3="يتجاوز التوقعات", Main!AB3="يتجاوز التوقعات بكثير")), "يتجاوز التوقعات", IF(AND(Main!AA3="يتجاوز التوقعات", Main!AB3="يتجاوز التوقعات"), "يتجاوز التوقعات", IF(OR(AND(Main!AA3="يتجاوز التوقعات", Main!AB3="يفي بالتوقعات"), AND(Main!AA3="يفي بالتوقعات", Main!AB3="يتجاوز التوقعات")), "يفي بالتوقعات", IF(AND(Main!AA3="يفي بالتوقعات", Main!AB3="يفي بالتوقعات"), "يفي بالتوقعات", IF(OR(AND(Main!AA3="يفي بالتوقعات", Main!AB3="يفي بالتوقعات جزئياً"), AND(Main!AA3="يفي بالتوقعات جزئياً", Main!AB3="يفي بالتوقعات")), "يفي بالتوقعات جزئياً", IF(AND(Main!AA3="يفي بالتوقعات جزئياً", Main!AB3="يفي بالتوقعات جزئياً"), "يفي بالتوقعات جزئياً", "" ))))))) -> يتجاوز التوقعات بكثير | CL3: =IF(AND(Main!AZ3="يتجاوز التوقعات بكثير", Main!BA3="يتجاوز التوقعات بكثير"), "يتجاوز التوقعات بكثير", IF(OR(AND(Main!AZ3="يتجاوز التوقعات بكثير", Main!BA3="يتجاوز التوقعات"), AND(Main!AZ3="يتجاوز التوقعات", Main!BA3="يتجاوز التوقعات بكثير")), "يتجاوز التوقعات", IF(AND(Main!AZ3="يتجاوز التوقعات", Main!BA3="يتجاوز التوقعات"), "يتجاوز التوقعات", IF(OR(AND(Main!AZ3="يتجاوز التوقعات", Main!BA3="يفي بالتوقعات"), AND(Main!AZ3="يفي بالتوقعات", Main!BA3="يتجاوز التوقعات")), "يفي بالتوقعات", IF(AND(Main!AZ3="يفي بالتوقعات", Main!BA3="يفي بالتوقعات"), "يفي بالتوقعات", IF(OR(AND(Main!AZ3="يفي بالتوقعات", Main!BA3="يفي بالتوقعات جزئياً"), AND(Main!AZ3="يفي بالتوقعات جزئياً", Main!BA3="يفي بالتوقعات")), "يفي بالتوقعات جزئياً", IF(AND(Main!AZ3="يفي بالتوقعات جزئياً", Main!BA3="يفي بالتوقعات جزئياً"), "يفي بالتوقعات جزئياً", "" )))))))
A4: 68 | B4: 45811.361 | C4: 45811.363 | D4: 890302057@moe.bh | E4: Afaf Hussain Ahmed Ebrahim Hussain Ahmed Ebrahim | F4: عفاف حسين أحمد | G4: قسم الحاسب الآلي | H4: 2024-2025 | J4: الفصل الدراسي الأول | K4: زيارات القيادة الوسطى لجميع المعلمات | M4: استمارة الزيارة الصفية | N4: الزيارة الثالثة | O4: يتجاوز التوقعات بكثير | P4: يتجاوز التوقعات بكثير | Q4: يتجاوز التوقعات بكثير | R4: يتجاوز التوقعات | S4: يتجاوز التوقعات بكثير | T4: يتجاوز التوقعات بكثير | U4: يتجاوز التوقعات بكثير | V4: يتجاوز التوقعات بكثير | W4: يتجاوز التوقعات | X4: يتجاوز التوقعات بكثير | Y4: يتجاوز التوقعات بكثير | Z4: يتجاوز التوقعات بكثير | AA4: يتجاوز التوقعات بكثير | AB4: يتجاوز التوقعات بكثير | AC4: يتجاوز التوقعات بكثير | AD4: يتجاوز التوقعات بكثير | AE4: يتجاوز التوقعات بكثير | AF4: يتجاوز التوقعات بكثير | AG4: ابتدعت في مراحل عرض الدرس وعرض انجازات الطالبات والاحتفاء بها | AH4: - | CK4: =IF(AND(Main!AA4="يتجاوز التوقعات بكثير", Main!AB4="يتجاوز التوقعات بكثير"), "يتجاوز التوقعات بكثير", IF(OR(AND(Main!AA4="يتجاوز التوقعات بكثير", Main!AB4="يتجاوز التوقعات"), AND(Main!AA4="يتجاوز التوقعات", Main!AB4="يتجاوز التوقعات بكثير")), "يتجاوز التوقعات", IF(AND(Main!AA4="يتجاوز التوقعات", Main!AB4="يتجاوز التوقعات"), "يتجاوز التوقعات", IF(OR(AND(Main!AA4="يتجاوز التوقعات", Main!AB4="يفي بالتوقعات"), AND(Main!AA4="يفي بالتوقعات", Main!AB4="يتجاوز التوقعات")), "يفي بالتوقعات", IF(AND(Main!AA4="يفي بالتوقعات", Main!AB4="يفي بالتوقعات"), "يفي بالتوقعات", IF(OR(AND(Main!AA4="يفي بالتوقعات", Main!AB4="يفي بالتوقعات جزئياً"), AND(Main!AA4="يفي بالتوقعات جزئياً", Main!AB4="يفي بالتوقعات")), "يفي بالتوقعات جزئياً", IF(AND(Main!AA4="يفي بالتوقعات جزئياً", Main!AB4="يفي بالتوقعات جزئياً"), "يفي بالتوقعات جزئياً", "" ))))))) -> يتجاوز التوقعات بكثير | CL4: =IF(AND(Main!AZ4="يتجاوز التوقعات بكثير", Main!BA4="يتجاوز التوقعات بكثير"), "يتجاوز التوقعات بكثير", IF(OR(AND(Main!AZ4="يتجاوز التوقعات بكثير", Main!BA4="يتجاوز التوقعات"), AND(Main!AZ4="يتجاوز التوقعات", Main!BA4="يتجاوز التوقعات بكثير")), "يتجاوز التوقعات", IF(AND(Main!AZ4="يتجاوز التوقعات", Main!BA4="يتجاوز التوقعات"), "يتجاوز التوقعات", IF(OR(AND(Main!AZ4="يتجاوز التوقعات", Main!BA4="يفي بالتوقعات"), AND(Main!AZ4="يفي بالتوقعات", Main!BA4="يتجاوز التوقعات")), "يفي بالتوقعات", IF(AND(Main!AZ4="يفي بالتوقعات", Main!BA4="يفي بالتوقعات"), "يفي بالتوقعات", IF(OR(AND(Main!AZ4="يفي بالتوقعات", Main!BA4="يفي بالتوقعات جزئياً"), AND(Main!AZ4="يفي بالتوقعات جزئياً", Main!BA4="يفي بالتوقعات")), "يفي بالتوقعات جزئياً", IF(AND(Main!AZ4="يفي بالتوقعات جزئياً", Main!BA4="يفي بالتوقعات جزئياً"), "يفي بالتوقعات جزئياً", "" )))))))
A5: 69 | B5: 45811.363 | C5: 45811.37 | D5: 890302057@moe.bh | E5: Afaf Hussain Ahmed Ebrahim Hussain Ahmed Ebrahim | F5: عفاف حسين أحمد | G5: قسم الحاسب الآلي | H5: 2024-2025 | J5: الفصل الدراسي الثاني | K5: التقييم الذاتي لجميع المعلمات | AN5: يتجاوز التوقعات بكثير | AO5: يتجاوز التوقعات بكثير | AP5: يتجاوز التوقعات بكثير | AQ5: يتجاوز التوقعات بكثير | AR5: يتجاوز التوقعات بكثير | AS5: يتجاوز التوقعات بكثير | AT5: يتجاوز التوقعات بكثير | AU5: يتجاوز التوقعات بكثير | AV5: يتجاوز التوقعات بكثير | AW5: يتجاوز التوقعات بكثير | AX5: يتجاوز التوقعات بكثير | AY5: يتجاوز التوقعات بكثير | AZ5: يتجاوز التوقعات بكثير | BA5: يتجاوز التوقعات بكثير | BB5: يتجاوز التوقعات بكثير | BC5: يتجاوز التوقعات بكثير | BD5: يتجاوز التوقعات بكثير | BE5: يتجاوز التوقعات بكثير | BF5: أُراعي مستويات الطالبات المختلفة | BG5: الحاجة لتطوير استراتيجيات تعزز من استقلالية الطالبات في التعلم وتحمل المسؤولية. | BH5: تشجيع تنظيم لقاءات دورية مع زملاء التخصص لتبادل الخبرات والتجارب التدريسية الناجحة. | BI5: التركيز على تنمية مهارات طرح أسئلة تنمي التفكير النقدي، التحليلي، والاستنتاجي لدى الطالبات. | CK5: =IF(AND(Main!AA5="يتجاوز التوقعات بكثير", Main!AB5="يتجاوز التوقعات بكثير"), "يتجاوز التوقعات بكثير", IF(OR(AND(Main!AA5="يتجاوز التوقعات بكثير", Main!AB5="يتجاوز التوقعات"), AND(Main!AA5="يتجاوز التوقعات", Main!AB5="يتجاوز التوقعات بكثير")), "يتجاوز التوقعات", IF(AND(Main!AA5="يتجاوز التوقعات", Main!AB5="يتجاوز التوقعات"), "يتجاوز التوقعات", IF(OR(AND(Main!AA5="يتجاوز التوقعات", Main!AB5="يفي بالتوقعات"), AND(Main!AA5="يفي بالتوقعات", Main!AB5="يتجاوز التوقعات")), "يفي بالتوقعات", IF(AND(Main!AA5="يفي بالتوقعات", Main!AB5="يفي بالتوقعات"), "يفي بالتوقعات", IF(OR(AND(Main!AA5="يفي بالتوقعات", Main!AB5="يفي بالتوقعات جزئياً"), AND(Main!AA5="يفي بالتوقعات جزئياً", Main!AB5="يفي بالتوقعات")), "يفي بالتوقعات جزئياً", IF(AND(Main!AA5="يفي بالتوقعات جزئياً", Main!AB5="يفي بالتوقعات جزئياً"), "يفي بالتوقعات جزئياً", "" ))))))) | CL5: =IF(AND(Main!AZ5="يتجاوز التوقعات بكثير", Main!BA5="يتجاوز التوقعات بكثير"), "يتجاوز التوقعات بكثير", IF(OR(AND(Main!AZ5="يتجاوز التوقعات بكثير", Main!BA5="يتجاوز التوقعات"), AND(Main!AZ5="يتجاوز التوقعات", Main!BA5="يتجاوز التوقعات بكثير")), "يتجاوز التوقعات", IF(AND(Main!AZ5="يتجاوز التوقعات", Main!BA5="يتجاوز التوقعات"), "يتجاوز التوقعات", IF(OR(AND(Main!AZ5="يتجاوز التوقعات", Main!BA5="يفي بالتوقعات"), AND(Main!AZ5="يفي بالتوقعات", Main!BA5="يتجاوز التوقعات")), "يفي بالتوقعات", IF(AND(Main!AZ5="يفي بالتوقعات", Main!BA5="يفي بالتوقعات"), "يفي بالتوقعات", IF(OR(AND(Main!AZ5="يفي بالتوقعات", Main!BA5="يفي بالتوقعات جزئياً"), AND(Main!AZ5="يفي بالتوقعات جزئياً", Main!BA5="يفي بالتوقعات")), "يفي بالتوقعات جزئياً", IF(AND(Main!AZ5="يفي بالتوقعات جزئياً", Main!BA5="يفي بالتوقعات جزئياً"), "يفي بالتوقعات جزئياً", "" ))))))) -> يتجاوز التوقعات بكثير
A6: 70 | B6: 45811.375 | C6: 45811.376 | D6: 890302057@moe.bh | E6: Afaf Hussain Ahmed Ebrahim Hussain Ahmed Ebrahim | F6: أمينة محمد موسى | G6: قسم الحاسب الآلي | H6: 2024-2025 | J6: الفصل الدراسي الأول | K6: زيارات القيادة العليا للقيادة الوسطى | N6: الزيارة الأولى | O6: يتجاوز التوقعات بكثير | P6: يتجاوز التوقعات بكثير | Q6: يتجاوز التوقعات بكثير | R6: يتجاوز التوقعات بكثير | S6: يتجاوز التوقعات بكثير | T6: يتجاوز التوقعات بكثير | U6: يتجاوز التوقعات بكثير | V6: يتجاوز التوقعات بكثير | W6: يتجاوز التوقعات بكثير | X6: يتجاوز التوقعات بكثير | Y6: يتجاوز التوقعات بكثير | Z6: يتجاوز التوقعات بكثير | AA6: يتجاوز التوقعات بكثير | AB6: يتجاوز التوقعات بكثير | AC6: يتجاوز التوقعات بكثير | AD6: يتجاوز التوقعات بكثير | AE6: يتجاوز التوقعات بكثير | AF6: يتجاوز التوقعات بكثير | AG6: استراتيجيات تعليم وتعلم متنوعة ومبتكرة آلية رائعة في تحفيز جميع الطالبات على المشاركة دعم جميع فئات الطالبات- | AH6: - | CK6: =IF(AND(Main!AA6="يتجاوز التوقعات بكثير", Main!AB6="يتجاوز التوقعات بكثير"), "يتجاوز التوقعات بكثير", IF(OR(AND(Main!AA6="يتجاوز التوقعات بكثير", Main!AB6="يتجاوز التوقعات"), AND(Main!AA6="يتجاوز التوقعات", Main!AB6="يتجاوز التوقعات بكثير")), "يتجاوز التوقعات", IF(AND(Main!AA6="يتجاوز التوقعات", Main!AB6="يتجاوز التوقعات"), "يتجاوز التوقعات", IF(OR(AND(Main!AA6="يتجاوز التوقعات", Main!AB6="يفي بالتوقعات"), AND(Main!AA6="يفي بالتوقعات", Main!AB6="يتجاوز التوقعات")), "يفي بالتوقعات", IF(AND(Main!AA6="يفي بالتوقعات", Main!AB6="يفي بالتوقعات"), "يفي بالتوقعات", IF(OR(AND(Main!AA6="يفي بالتوقعات", Main!AB6="يفي بالتوقعات جزئياً"), AND(Main!AA6="يفي بالتوقعات جزئياً", Main!AB6="يفي بالتوقعات")), "يفي بالتوقعات جزئياً", IF(AND(Main!AA6="يفي بالتوقعات جزئياً", Main!AB6="يفي بالتوقعات جزئياً"), "يفي بالتوقعات جزئياً", "" ))))))) -> يتجاوز التوقعات بكثير | CL6: =IF(AND(Main!AZ6="يتجاوز التوقعات بكثير", Main!BA6="يتجاوز التوقعات بكثير"), "يتجاوز التوقعات بكثير", IF(OR(AND(Main!AZ6="يتجاوز التوقعات بكثير", Main!BA6="يتجاوز التوقعات"), AND(Main!AZ6="يتجاوز التوقعات", Main!BA6="يتجاوز التوقعات بكثير")), "يتجاوز التوقعات", IF(AND(Main!AZ6="يتجاوز التوقعات", Main!BA6="يتجاوز التوقعات"), "يتجاوز التوقعات", IF(OR(AND(Main!AZ6="يتجاوز التوقعات", Main!BA6="يفي بالتوقعات"), AND(Main!AZ6="يفي بالتوقعات", Main!BA6="يتجاوز التوقعات")), "يفي بالتوقعات", IF(AND(Main!AZ6="يفي بالتوقعات", Main!BA6="يفي بالتوقعات"), "يفي بالتوقعات", IF(OR(AND(Main!AZ6="يفي بالتوقعات", Main!BA6="يفي بالتوقعات جزئياً"), AND(Main!AZ6="يفي بالتوقعات جزئياً", Main!BA6="يفي بالتوقعات")), "يفي بالتوقعات جزئياً", IF(AND(Main!AZ6="يفي بالتوقعات جزئياً", Main!BA6="يفي بالتوقعات جزئياً"), "يفي بالتوقعات جزئياً", "" )))))))
A7: 71 | B7: 45811.376 | C7: 45811.377 | D7: 890302057@moe.bh | E7: Afaf Hussain Ahmed Ebrahim Hussain Ahmed Ebrahim | F7: أمينة محمد موسى | G7: قسم الحاسب الآلي | H7: 2024-2025 | J7: الفصل الدراسي الأول | K7: زيارات القيادة العليا للقيادة الوسطى | N7: الزيارة الثانية | O7: يتجاوز التوقعات بكثير | P7: يتجاوز التوقعات بكثير | Q7: يتجاوز التوقعات بكثير | R7: يتجاوز التوقعات بكثير | S7: يتجاوز التوقعات بكثير | T7: يتجاوز التوقعات بكثير | U7: يتجاوز التوقعات بكثير | V7: يتجاوز التوقعات بكثير | W7: يتجاوز التوقعات بكثير | X7: يتجاوز التوقعات بكثير | Y7: يتجاوز التوقعات بكثير | Z7: يتجاوز التوقعات بكثير | AA7: يتجاوز التوقعات بكثير | AB7: يتجاوز التوقعات بكثير | AC7: يتجاوز التوقعات بكثير | AD7: يتجاوز التوقعات بكثير | AE7: يتجاوز التوقعات بكثير | AF7: يتجاوز التوقعات بكثير | AG7: ابتدعت في مراحل عرض الدرس وعرض انجازات الطالبات والاحتفاء بها | AH7: - | CK7: =IF(AND(Main!AA7="يتجاوز التوقعات بكثير", Main!AB7="يتجاوز التوقعات بكثير"), "يتجاوز التوقعات بكثير", IF(OR(AND(Main!AA7="يتجاوز التوقعات بكثير", Main!AB7="يتجاوز التوقعات"), AND(Main!AA7="يتجاوز التوقعات", Main!AB7="يتجاوز التوقعات بكثير")), "يتجاوز التوقعات", IF(AND(Main!AA7="يتجاوز التوقعات", Main!AB7="يتجاوز التوقعات"), "يتجاوز التوقعات", IF(OR(AND(Main!AA7="يتجاوز التوقعات", Main!AB7="يفي بالتوقعات"), AND(Main!AA7="يفي بالتوقعات", Main!AB7="يتجاوز التوقعات")), "يفي بالتوقعات", IF(AND(Main!AA7="يفي بالتوقعات", Main!AB7="يفي بالتوقعات"), "يفي بالتوقعات", IF(OR(AND(Main!AA7="يفي بالتوقعات", Main!AB7="يفي بالتوقعات جزئياً"), AND(Main!AA7="يفي بالتوقعات جزئياً", Main!AB7="يفي بالتوقعات")), "يفي بالتوقعات جزئياً", IF(AND(Main!AA7="يفي بالتوقعات جزئياً", Main!AB7="يفي بالتوقعات جزئياً"), "يفي بالتوقعات جزئياً", "" ))))))) -> يتجاوز التوقعات بكثير | CL7: =IF(AND(Main!AZ7="يتجاوز التوقعات بكثير", Main!BA7="يتجاوز التوقعات بكثير"), "يتجاوز التوقعات بكثير", IF(OR(AND(Main!AZ7="يتجاوز التوقعات بكثير", Main!BA7="يتجاوز التوقعات"), AND(Main!AZ7="يتجاوز التوقعات", Main!BA7="يتجاوز التوقعات بكثير")), "يتجاوز التوقعات", IF(AND(Main!AZ7="يتجاوز التوقعات", Main!BA7="يتجاوز التوقعات"), "يتجاوز التوقعات", IF(OR(AND(Main!AZ7="يتجاوز التوقعات", Main!BA7="يفي بالتوقعات"), AND(Main!AZ7="يفي بالتوقعات", Main!BA7="يتجاوز التوقعات")), "يفي بالتوقعات", IF(AND(Main!AZ7="يفي بالتوقعات", Main!BA7="يفي بالتوقعات"), "يفي بالتوقعات", IF(OR(AND(Main!AZ7="يفي بالتوقعات", Main!BA7="يفي بالتوقعات جزئياً"), AND(Main!AZ7="يفي بالتوقعات جزئياً", Main!BA7="يفي بالتوقعات")), "يفي بالتوقعات جزئياً", IF(AND(Main!AZ7="يفي بالتوقعات جزئياً", Main!BA7="يفي بالتوقعات جزئياً"), "يفي بالتوقعات جزئياً", "" )))))))
A8: 72 | B8: 45811.377 | C8: 45811.378 | D8: 890302057@moe.bh | E8: Afaf Hussain Ahmed Ebrahim Hussain Ahmed Ebrahim | F8: أمينة محمد موسى | G8: قسم الحاسب الآلي | H8: 2024-2025 | J8: الفصل الدراسي الأول | K8: زيارات القيادة العليا للقيادة الوسطى | N8: الزيارة الثالثة | O8: يتجاوز التوقعات بكثير | P8: يتجاوز التوقعات بكثير | Q8: يتجاوز التوقعات بكثير | R8: يتجاوز التوقعات بكثير | S8: يتجاوز التوقعات بكثير | T8: يتجاوز التوقعات بكثير | U8: يتجاوز التوقعات بكثير | V8: يتجاوز التوقعات بكثير | W8: يتجاوز التوقعات بكثير | X8: يتجاوز التوقعات بكثير | Y8: يتجاوز التوقعات بكثير | Z8: يتجاوز التوقعات بكثير | AA8: يتجاوز التوقعات بكثير | AB8: يتجاوز التوقعات بكثير | AC8: يتجاوز التوقعات بكثير | AD8: يتجاوز التوقعات بكثير | AE8: يتجاوز التوقعات بكثير | AF8: يتجاوز التوقعات بكثير | AG8: تدريب الطالبات على المهارات بشكل منظم ومبتكر وتفعيل تعليم الأقران والتعلم الذاتي بشكل فاعل | AH8: - | CK8: =IF(AND(Main!AA8="يتجاوز التوقعات بكثير", Main!AB8="يتجاوز التوقعات بكثير"), "يتجاوز التوقعات بكثير", IF(OR(AND(Main!AA8="يتجاوز التوقعات بكثير", Main!AB8="يتجاوز التوقعات"), AND(Main!AA8="يتجاوز التوقعات", Main!AB8="يتجاوز التوقعات بكثير")), "يتجاوز التوقعات", IF(AND(Main!AA8="يتجاوز التوقعات", Main!AB8="يتجاوز التوقعات"), "يتجاوز التوقعات", IF(OR(AND(Main!AA8="يتجاوز التوقعات", Main!AB8="يفي بالتوقعات"), AND(Main!AA8="يفي بالتوقعات", Main!AB8="يتجاوز التوقعات")), "يفي بالتوقعات", IF(AND(Main!AA8="يفي بالتوقعات", Main!AB8="يفي بالتوقعات"), "يفي بالتوقعات", IF(OR(AND(Main!AA8="يفي بالتوقعات", Main!AB8="يفي بالتوقعات جزئياً"), AND(Main!AA8="يفي بالتوقعات جزئياً", Main!AB8="يفي بالتوقعات")), "يفي بالتوقعات جزئياً", IF(AND(Main!AA8="يفي بالتوقعات جزئياً", Main!AB8="يفي بالتوقعات جزئياً"), "يفي بالتوقعات جزئياً", "" ))))))) -> يتجاوز التوقعات بكثير | CL8: =IF(AND(Main!AZ8="يتجاوز التوقعات بكثير", Main!BA8="يتجاوز التوقعات بكثير"), "يتجاوز التوقعات بكثير", IF(OR(AND(Main!AZ8="يتجاوز التوقعات بكثير", Main!BA8="يتجاوز التوقعات"), AND(Main!AZ8="يتجاوز التوقعات", Main!BA8="يتجاوز التوقعات بكثير")), "يتجاوز التوقعات", IF(AND(Main!AZ8="يتجاوز التوقعات", Main!BA8="يتجاوز التوقعات"), "يتجاوز التوقعات", IF(OR(AND(Main!AZ8="يتجاوز التوقعات", Main!BA8="يفي بالتوقعات"), AND(Main!AZ8="يفي بالتوقعات", Main!BA8="يتجاوز التوقعات")), "يفي بالتوقعات", IF(AND(Main!AZ8="يفي بالتوقعات", Main!BA8="يفي بالتوقعات"), "يفي بالتوقعات", IF(OR(AND(Main!AZ8="يفي بالتوقعات", Main!BA8="يفي بالتوقعات جزئياً"), AND(Main!AZ8="يفي بالتوقعات جزئياً", Main!BA8="يفي بالتوقعات")), "يفي بالتوقعات جزئياً", IF(AND(Main!AZ8="يفي بالتوقعات جزئياً", Main!BA8="يفي بالتوقعات جزئياً"), "يفي بالتوقعات جزئياً", "" )))))))
A9: 73 | B9: 45811.378 | C9: 45811.382 | D9: 890302057@moe.bh | E9: Afaf Hussain Ahmed Ebrahim Hussain Ahmed Ebrahim | F9: مريم محمد الحاي | G9: قسم الحاسب الآلي | H9: 2024-2025 | J9: الفصل الدراسي الأول | K9: زيارات القيادة الوسطى لجميع المعلمات | M9: استمارة الزيارة الصفية | N9: الزيارة الأولى | O9: يتجاوز التوقعات بكثير | P9: يتجاوز التوقعات بكثير | Q9: يتجاوز التوقعات بكثير | R9: يتجاوز التوقعات بكثير | S9: يتجاوز التوقعات بكثير | T9: يتجاوز التوقعات بكثير | U9: يتجاوز التوقعات | V9: يتجاوز التوقعات بكثير | W9: يتجاوز التوقعات بكثير | X9: يتجاوز التوقعات | Y9: يتجاوز التوقعات بكثير | Z9: يتجاوز التوقعات بكثير | AA9: يتجاوز التوقعات بكثير | AB9: يتجاوز التوقعات بكثير | AC9: يتجاوز التوقعات بكثير | AD9: يتجاوز التوقعات بكثير | AE9: يتجاوز التوقعات بكثير | AF9: يتجاوز التوقعات بكثير | AG9: تدريب الطالبات على المهارات بشكل منظم ومبتكر | AH9: - | CK9: =IF(AND(Main!AA9="يتجاوز التوقعات بكثير", Main!AB9="يتجاوز التوقعات بكثير"), "يتجاوز التوقعات بكثير", IF(OR(AND(Main!AA9="يتجاوز التوقعات بكثير", Main!AB9="يتجاوز التوقعات"), AND(Main!AA9="يتجاوز التوقعات", Main!AB9="يتجاوز التوقعات بكثير")), "يتجاوز التوقعات", IF(AND(Main!AA9="يتجاوز التوقعات", Main!AB9="يتجاوز التوقعات"), "يتجاوز التوقعات", IF(OR(AND(Main!AA9="يتجاوز التوقعات", Main!AB9="يفي بالتوقعات"), AND(Main!AA9="يفي بالتوقعات", Main!AB9="يتجاوز التوقعات")), "يفي بالتوقعات", IF(AND(Main!AA9="يفي بالتوقعات", Main!AB9="يفي بالتوقعات"), "يفي بالتوقعات", IF(OR(AND(Main!AA9="يفي بالتوقعات", Main!AB9="يفي بالتوقعات جزئياً"), AND(Main!AA9="يفي بالتوقعات جزئياً", Main!AB9="يفي بالتوقعات")), "يفي بالتوقعات جزئياً", IF(AND(Main!AA9="يفي بالتوقعات جزئياً", Main!AB9="يفي بالتوقعات جزئياً"), "يفي بالتوقعات جزئياً", "" ))))))) -> يتجاوز التوقعات بكثير | CL9: =IF(AND(Main!AZ9="يتجاوز التوقعات بكثير", Main!BA9="يتجاوز التوقعات بكثير"), "يتجاوز التوقعات بكثير", IF(OR(AND(Main!AZ9="يتجاوز التوقعات بكثير", Main!BA9="يتجاوز التوقعات"), AND(Main!AZ9="يتجاوز التوقعات", Main!BA9="يتجاوز التوقعات بكثير")), "يتجاوز التوقعات", IF(AND(Main!AZ9="يتجاوز التوقعات", Main!BA9="يتجاوز التوقعات"), "يتجاوز التوقعات", IF(OR(AND(Main!AZ9="يتجاوز التوقعات", Main!BA9="يفي بالتوقعات"), AND(Main!AZ9="يفي بالتوقعات", Main!BA9="يتجاوز التوقعات")), "يفي بالتوقعات", IF(AND(Main!AZ9="يفي بالتوقعات", Main!BA9="يفي بالتوقعات"), "يفي بالتوقعات", IF(OR(AND(Main!AZ9="يفي بالتوقعات", Main!BA9="يفي بالتوقعات جزئياً"), AND(Main!AZ9="يفي بالتوقعات جزئياً", Main!BA9="يفي بالتوقعات")), "يفي بالتوقعات جزئياً", IF(AND(Main!AZ9="يفي بالتوقعات جزئياً", Main!BA9="يفي بالتوقعات جزئياً"), "يفي بالتوقعات جزئياً", "" )))))))
A10: 74 | B10: 45811.383 | C10: 45811.384 | D10: 890302057@moe.bh | E10: Afaf Hussain Ahmed Ebrahim Hussain Ahmed Ebrahim | F10: مريم محمد الحاي | G10: قسم الحاسب الآلي | H10: 2024-2025 | J10: الفصل الدراسي الأول | K10: زيارات القيادة الوسطى لجميع المعلمات | M10: استمارة الزيارة الصفية | N10: الزيارة الثانية | O10: يتجاوز التوقعات بكثير | P10: يتجاوز التوقعات بكثير | Q10: يتجاوز التوقعات بكثير | R10: يتجاوز التوقعات | S10: يتجاوز التوقعات بكثير | T10: يتجاوز التوقعات بكثير | U10: يتجاوز التوقعات | V10: يتجاوز التوقعات | W10: يتجاوز التوقعات | X10: يتجاوز التوقعات | Y10: يتجاوز التوقعات بكثير | Z10: يتجاوز التوقعات | AA10: يتجاوز التوقعات بكثير | AB10: يتجاوز التوقعات بكثير | AC10: يتجاوز التوقعات بكثير | AD10: يتجاوز التوقعات بكثير | AE10: يتجاوز التوقعات بكثير | AF10: يتجاوز التوقعات بكثير | AG10: استراتيجيات تعليم وتعلم متنوعة ومبتكرة | AH10: - | CK10: =IF(AND(Main!AA10="يتجاوز التوقعات بكثير", Main!AB10="يتجاوز التوقعات بكثير"), "يتجاوز التوقعات بكثير", IF(OR(AND(Main!AA10="يتجاوز التوقعات بكثير", Main!AB10="يتجاوز التوقعات"), AND(Main!AA10="يتجاوز التوقعات", Main!AB10="يتجاوز التوقعات بكثير")), "يتجاوز التوقعات", IF(AND(Main!AA10="يتجاوز التوقعات", Main!AB10="يتجاوز التوقعات"), "يتجاوز التوقعات", IF(OR(AND(Main!AA10="يتجاوز التوقعات", Main!AB10="يفي بالتوقعات"), AND(Main!AA10="يفي بالتوقعات", Main!AB10="يتجاوز التوقعات")), "يفي بالتوقعات", IF(AND(Main!AA10="يفي بالتوقعات", Main!AB10="يفي بالتوقعات"), "يفي بالتوقعات", IF(OR(AND(Main!AA10="يفي بالتوقعات", Main!AB10="يفي بالتوقعات جزئياً"), AND(Main!AA10="يفي بالتوقعات جزئياً", Main!AB10="يفي بالتوقعات")), "يفي بالتوقعات جزئياً", IF(AND(Main!AA10="يفي بالتوقعات جزئياً", Main!AB10="يفي بالتوقعات جزئياً"), "يفي بالتوقعات جزئياً", "" ))))))) -> يتجاوز التوقعات بكثير | CL10: =IF(AND(Main!AZ10="يتجاوز التوقعات بكثير", Main!BA10="يتجاوز التوقعات بكثير"), "يتجاوز التوقعات بكثير", IF(OR(AND(Main!AZ10="يتجاوز التوقعات بكثير", Main!BA10="يتجاوز التوقعات"), AND(Main!AZ10="يتجاوز التوقعات", Main!BA10="يتجاوز التوقعات بكثير")), "يتجاوز التوقعات", IF(AND(Main!AZ10="يتجاوز التوقعات", Main!BA10="يتجاوز التوقعات"), "يتجاوز التوقعات", IF(OR(AND(Main!AZ10="يتجاوز التوقعات", Main!BA10="يفي بالتوقعات"), AND(Main!AZ10="يفي بالتوقعات", Main!BA10="يتجاوز التوقعات")), "يفي بالتوقعات", IF(AND(Main!AZ10="يفي بالتوقعات", Main!BA10="يفي بالتوقعات"), "يفي بالتوقعات", IF(OR(AND(Main!AZ10="يفي بالتوقعات", Main!BA10="يفي بالتوقعات جزئياً"), AND(Main!AZ10="يفي بالتوقعات جزئياً", Main!BA10="يفي بالتوقعات")), "يفي بالتوقعات جزئياً", IF(AND(Main!AZ10="يفي بالتوقعات جزئياً", Main!BA10="يفي بالتوقعات جزئياً"), "يفي بالتوقعات جزئياً", "" )))))))
A11: 75 | B11: 45811.384 | C11: 45811.385 | D11: 890302057@moe.bh | E11: Afaf Hussain Ahmed Ebrahim Hussain Ahmed Ebrahim | F11: مريم محمد الحاي | G11: قسم الحاسب الآلي | H11: 2024-2025 | J11: الفصل الدراسي الأول | K11: زيارات القيادة الوسطى لجميع المعلمات | M11: استمارة الزيارة الصفية | N11: الزيارة الثالثة | O11: يتجاوز التوقعات بكثير | P11: يتجاوز التوقعات بكثير | Q11: يتجاوز التوقعات بكثير | R11: يتجاوز التوقعات بكثير | S11: يتجاوز التوقعات بكثير | T11: يتجاوز التوقعات بكثير | U11: يتجاوز التوقعات | V11: يتجاوز التوقعات بكثير | W11: يتجاوز التوقعات بكثير | X11: يتجاوز التوقعات بكثير | Y11: يتجاوز التوقعات بكثير | Z11: يتجاوز التوقعات بكثير | AA11: يتجاوز التوقعات بكثير | AB11: يتجاوز التوقعات بكثير | AC11: يتجاوز التوقعات بكثير | AD11: يتجاوز التوقعات بكثير | AE11: يتجاوز التوقعات بكثير | AF11: يتجاوز التوقعات | AG11: عرض انجازات الطالبات والاحتفاء بها | AH11: - | CK11: =IF(AND(Main!AA11="يتجاوز التوقعات بكثير", Main!AB11="يتجاوز التوقعات بكثير"), "يتجاوز التوقعات بكثير", IF(OR(AND(Main!AA11="يتجاوز التوقعات بكثير", Main!AB11="يتجاوز التوقعات"), AND(Main!AA11="يتجاوز التوقعات", Main!AB11="يتجاوز التوقعات بكثير")), "يتجاوز التوقعات", IF(AND(Main!AA11="يتجاوز التوقعات", Main!AB11="يتجاوز التوقعات"), "يتجاوز التوقعات", IF(OR(AND(Main!AA11="يتجاوز التوقعات", Main!AB11="يفي بالتوقعات"), AND(Main!AA11="يفي بالتوقعات", Main!AB11="يتجاوز التوقعات")), "يفي بالتوقعات", IF(AND(Main!AA11="يفي بالتوقعات", Main!AB11="يفي بالتوقعات"), "يفي بالتوقعات", IF(OR(AND(Main!AA11="يفي بالتوقعات", Main!AB11="يفي بالتوقعات جزئياً"), AND(Main!AA11="يفي بالتوقعات جزئياً", Main!AB11="يفي بالتوقعات")), "يفي بالتوقعات جزئياً", IF(AND(Main!AA11="يفي بالتوقعات جزئياً", Main!AB11="يفي بالتوقعات جزئياً"), "يفي بالتوقعات جزئياً", "" ))))))) -> يتجاوز التوقعات بكثير | CL11: =IF(AND(Main!AZ11="يتجاوز التوقعات بكثير", Main!BA11="يتجاوز التوقعات بكثير"), "يتجاوز التوقعات بكثير", IF(OR(AND(Main!AZ11="يتجاوز التوقعات بكثير", Main!BA11="يتجاوز التوقعات"), AND(Main!AZ11="يتجاوز التوقعات", Main!BA11="يتجاوز التوقعات بكثير")), "يتجاوز التوقعات", IF(AND(Main!AZ11="يتجاوز التوقعات", Main!BA11="يتجاوز التوقعات"), "يتجاوز التوقعات", IF(OR(AND(Main!AZ11="يتجاوز التوقعات", Main!BA11="يفي بالتوقعات"), AND(Main!AZ11="يفي بالتوقعات", Main!BA11="يتجاوز التوقعات")), "يفي بالتوقعات", IF(AND(Main!AZ11="يفي بالتوقعات", Main!BA11="يفي بالتوقعات"), "يفي بالتوقعات", IF(OR(AND(Main!AZ11="يفي بالتوقعات", Main!BA11="يفي بالتوقعات جزئياً"), AND(Main!AZ11="يفي بالتوقعات جزئياً", Main!BA11="يفي بالتوقعات")), "يفي بالتوقعات جزئياً", IF(AND(Main!AZ11="يفي بالتوقعات جزئياً", Main!BA11="يفي بالتوقعات جزئياً"), "يفي بالتوقعات جزئياً", "" )))))))
A12: 76 | B12: 45811.388 | C12: 45811.392 | D12: 840101929@moe.bh | E12: FATEMA ABDULAMEER ABDULLA HASAN | F12: رنى فرحان عوض بني خالد | G12: قسم المواد الاجتماعية | H12: 2024-2025 | J12: الفصل الدراسي الأول | K12: زيارات القيادة العليا للقيادة الوسطى | N12: الزيارة الأولى | O12: يتجاوز التوقعات بكثير | P12: يتجاوز التوقعات بكثير | Q12: يتجاوز التوقعات بكثير | R12: يتجاوز التوقعات بكثير | S12: يتجاوز التوقعات بكثير | T12: يتجاوز التوقعات بكثير | U12: يتجاوز التوقعات بكثير | V12: يتجاوز التوقعات بكثير | W12: يتجاوز التوقعات بكثير | X12: يتجاوز التوقعات بكثير | Y12: يتجاوز التوقعات بكثير | Z12: يتجاوز التوقعات بكثير | AA12: يتجاوز التوقعات بكثير | AB12: يتجاوز التوقعات بكثير | AC12: يتجاوز التوقعات بكثير | AD12: يتجاوز التوقعات بكثير | AE12: يتجاوز التوقعات بكثير | AF12: يتجاوز التوقعات بكثير | AG12: التنويع في الاستراتيجيات المبتكرة الفاعلة المناسبة للاطار الخامس وتقديم الدعم الاكاديمي بشكل فاعل ومتميز عند تطبيق الانشطة التعليمية | AH12: . | CK12: =IF(AND(Main!AA12="يتجاوز التوقعات بكثير", Main!AB12="يتجاوز التوقعات بكثير"), "يتجاوز التوقعات بكثير", IF(OR(AND(Main!AA12="يتجاوز التوقعات بكثير", Main!AB12="يتجاوز التوقعات"), AND(Main!AA12="يتجاوز التوقعات", Main!AB12="يتجاوز التوقعات بكثير")), "يتجاوز التوقعات", IF(AND(Main!AA12="يتجاوز التوقعات", Main!AB12="يتجاوز التوقعات"), "يتجاوز التوقعات", IF(OR(AND(Main!AA12="يتجاوز التوقعات", Main!AB12="يفي بالتوقعات"), AND(Main!AA12="يفي بالتوقعات", Main!AB12="يتجاوز التوقعات")), "يفي بالتوقعات", IF(AND(Main!AA12="يفي بالتوقعات", Main!AB12="يفي بالتوقعات"), "يفي بالتوقعات", IF(OR(AND(Main!AA12="يفي بالتوقعات", Main!AB12="يفي بالتوقعات جزئياً"), AND(Main!AA12="يفي بالتوقعات جزئياً", Main!AB12="يفي بالتوقعات")), "يفي بالتوقعات جزئياً", IF(AND(Main!AA12="يفي بالتوقعات جزئياً", Main!AB12="يفي بالتوقعات جزئياً"), "يفي بالتوقعات جزئياً", "" ))))))) -> يتجاوز التوقعات بكثير | CL12: =IF(AND(Main!AZ12="يتجاوز التوقعات بكثير", Main!BA12="يتجاوز التوقعات بكثير"), "يتجاوز التوقعات بكثير", IF(OR(AND(Main!AZ12="يتجاوز التوقعات بكثير", Main!BA12="يتجاوز التوقعات"), AND(Main!AZ12="يتجاوز التوقعات", Main!BA12="يتجاوز التوقعات بكثير")), "يتجاوز التوقعات", IF(AND(Main!AZ12="يتجاوز التوقعات", Main!BA12="يتجاوز التوقعات"), "يتجاوز التوقعات", IF(OR(AND(Main!AZ12="يتجاوز التوقعات", Main!BA12="يفي بالتوقعات"), AND(Main!AZ12="يفي بالتوقعات", Main!BA12="يتجاوز التوقعات")), "يفي بالتوقعات", IF(AND(Main!AZ12="يفي بالتوقعات", Main!BA12="يفي بالتوقعات"), "يفي بالتوقعات", IF(OR(AND(Main!AZ12="يفي بالتوقعات", Main!BA12="يفي بالتوقعات جزئياً"), AND(Main!AZ12="يفي بالتوقعات جزئياً", Main!BA12="يفي بالتوقعات")), "يفي بالتوقعات جزئياً", IF(AND(Main!AZ12="يفي بالتوقعات جزئياً", Main!BA12="يفي بالتوقعات جزئياً"), "يفي بالتوقعات جزئياً", "" )))))))
A13: 77 | B13: 45811.385 | C13: 45811.392 | D13: 890302057@moe.bh | E13: Afaf Hussain Ahmed Ebrahim Hussain Ahmed Ebrahim | F13: بشرى عبدالكريم يحيي | G13: قسم الحاسب الآلي | H13: 2024-2025 | J13: الفصل الدراسي الأول | K13: زيارات القيادة الوسطى لجميع المعلمات | M13: استمارة الزيارة الصفية | N13: الزيارة الأولى | O13: يتجاوز التوقعات بكثير | P13: يتجاوز التوقعات بكثير | Q13: يتجاوز التوقعات بكثير | R13: يتجاوز التوقعات بكثير | S13: يتجاوز التوقعات بكثير | T13: يتجاوز التوقعات بكثير | U13: يتجاوز التوقعات | V13: يتجاوز التوقعات | W13: يتجاوز التوقعات بكثير | X13: يتجاوز التوقعات بكثير | Y13: يتجاوز التوقعات بكثير | Z13: يتجاوز التوقعات بكثير | AA13: يتجاوز التوقعات بكثير | AB13: يتجاوز التوقعات بكثير | AC13: يتجاوز التوقعات بكثير | AD13: يتجاوز التوقعات بكثير | AE13: يتجاوز التوقعات بكثير | AF13: يتجاوز التوقعات بكثير | AG13: آلية رائعة في تحفيز جميع الطالبات على المشاركة | AH13: - | CK13: =IF(AND(Main!AA13="يتجاوز التوقعات بكثير", Main!AB13="يتجاوز التوقعات بكثير"), "يتجاوز التوقعات بكثير", IF(OR(AND(Main!AA13="يتجاوز التوقعات بكثير", Main!AB13="يتجاوز التوقعات"), AND(Main!AA13="يتجاوز التوقعات", Main!AB13="يتجاوز التوقعات بكثير")), "يتجاوز التوقعات", IF(AND(Main!AA13="يتجاوز التوقعات", Main!AB13="يتجاوز التوقعات"), "يتجاوز التوقعات", IF(OR(AND(Main!AA13="يتجاوز التوقعات", Main!AB13="يفي بالتوقعات"), AND(Main!AA13="يفي بالتوقعات", Main!AB13="يتجاوز التوقعات")), "يفي بالتوقعات", IF(AND(Main!AA13="يفي بالتوقعات", Main!AB13="يفي بالتوقعات"), "يفي بالتوقعات", IF(OR(AND(Main!AA13="يفي بالتوقعات", Main!AB13="يفي بالتوقعات جزئياً"), AND(Main!AA13="يفي بالتوقعات جزئياً", Main!AB13="يفي بالتوقعات")), "يفي بالتوقعات جزئياً", IF(AND(Main!AA13="يفي بالتوقعات جزئياً", Main!AB13="يفي بالتوقعات جزئياً"), "يفي بالتوقعات جزئياً", "" ))))))) -> يتجاوز التوقعات بكثير | CL13: =IF(AND(Main!AZ13="يتجاوز التوقعات بكثير", Main!BA13="يتجاوز التوقعات بكثير"), "يتجاوز التوقعات بكثير", IF(OR(AND(Main!AZ13="يتجاوز التوقعات بكثير", Main!BA13="يتجاوز التوقعات"), AND(Main!AZ13="يتجاوز التوقعات", Main!BA13="يتجاوز التوقعات بكثير")), "يتجاوز التوقعات", IF(AND(Main!AZ13="يتجاوز التوقعات", Main!BA13="يتجاوز التوقعات"), "يتجاوز التوقعات", IF(OR(AND(Main!AZ13="يتجاوز التوقعات", Main!BA13="يفي بالتوقعات"), AND(Main!AZ13="يفي بالتوقعات", Main!BA13="يتجاوز التوقعات")), "يفي بالتوقعات", IF(AND(Main!AZ13="يفي بالتوقعات", Main!BA13="يفي بالتوقعات"), "يفي بالتوقعات", IF(OR(AND(Main!AZ13="يفي بالتوقعات", Main!BA13="يفي بالتوقعات جزئياً"), AND(Main!AZ13="يفي بالتوقعات جزئياً", Main!BA13="يفي بالتوقعات")), "يفي بالتوقعات جزئياً", IF(AND(Main!AZ13="يفي بالتوقعات جزئياً", Main!BA13="يفي بالتوقعات جزئياً"), "يفي بالتوقعات جزئياً", "" )))))))
A14: 78 | B14: 45811.392 | C14: 45811.393 | D14: 890302057@moe.bh | E14: Afaf Hussain Ahmed Ebrahim Hussain Ahmed Ebrahim | F14: بشرى عبدالكريم يحيي | G14: قسم الحاسب الآلي | H14: 2024-2025 | J14: الفصل الدراسي الأول | K14: زيارات القيادة الوسطى لجميع المعلمات | M14: استمارة الزيارة الصفية | N14: الزيارة الثانية | O14: يتجاوز التوقعات بكثير | P14: يتجاوز التوقعات بكثير | Q14: يتجاوز التوقعات بكثير | R14: يتجاوز التوقعات بكثير | S14: يتجاوز التوقعات بكثير | T14: يتجاوز التوقعات بكثير | U14: يتجاوز التوقعات بكثير | V14: يتجاوز التوقعات بكثير | W14: يتجاوز التوقعات | X14: يتجاوز التوقعات بكثير | Y14: يتجاوز التوقعات بكثير | Z14: يتجاوز التوقعات بكثير | AA14: يتجاوز التوقعات بكثير | AB14: يتجاوز التوقعات بكثير | AC14: يتجاوز التوقعات بكثير | AD14: يتجاوز التوقعات بكثير | AE14: يتجاوز التوقعات بكثير | AF14: يتجاوز التوقعات بكثير | AG14: استراتيجيات تعليم وتعلم متنوعة ومبتكرة | AH14: - | CK14: =IF(AND(Main!AA14="يتجاوز التوقعات بكثير", Main!AB14="يتجاوز التوقعات بكثير"), "يتجاوز التوقعات بكثير", IF(OR(AND(Main!AA14="يتجاوز التوقعات بكثير", Main!AB14="يتجاوز التوقعات"), AND(Main!AA14="يتجاوز التوقعات", Main!AB14="يتجاوز التوقعات بكثير")), "يتجاوز التوقعات", IF(AND(Main!AA14="يتجاوز التوقعات", Main!AB14="يتجاوز التوقعات"), "يتجاوز التوقعات", IF(OR(AND(Main!AA14="يتجاوز التوقعات", Main!AB14="يفي بالتوقعات"), AND(Main!AA14="يفي بالتوقعات", Main!AB14="يتجاوز التوقعات")), "يفي بالتوقعات", IF(AND(Main!AA14="يفي بالتوقعات", Main!AB14="يفي بالتوقعات"), "يفي بالتوقعات", IF(OR(AND(Main!AA14="يفي بالتوقعات", Main!AB14="يفي بالتوقعات جزئياً"), AND(Main!AA14="يفي بالتوقعات جزئياً", Main!AB14="يفي بالتوقعات")), "يفي بالتوقعات جزئياً", IF(AND(Main!AA14="يفي بالتوقعات جزئياً", Main!AB14="يفي بالتوقعات جزئياً"), "يفي بالتوقعات جزئياً", "" ))))))) -> يتجاوز التوقعات بكثير | CL14: =IF(AND(Main!AZ14="يتجاوز التوقعات بكثير", Main!BA14="يتجاوز التوقعات بكثير"), "يتجاوز التوقعات بكثير", IF(OR(AND(Main!AZ14="يتجاوز التوقعات بكثير", Main!BA14="يتجاوز التوقعات"), AND(Main!AZ14="يتجاوز التوقعات", Main!BA14="يتجاوز التوقعات بكثير")), "يتجاوز التوقعات", IF(AND(Main!AZ14="يتجاوز التوقعات", Main!BA14="يتجاوز التوقعات"), "يتجاوز التوقعات", IF(OR(AND(Main!AZ14="يتجاوز التوقعات", Main!BA14="يفي بالتوقعات"), AND(Main!AZ14="يفي بالتوقعات", Main!BA14="يتجاوز التوقعات")), "يفي بالتوقعات", IF(AND(Main!AZ14="يفي بالتوقعات", Main!BA14="يفي بالتوقعات"), "يفي بالتوقعات", IF(OR(AND(Main!AZ14="يفي بالتوقعات", Main!BA14="يفي بالتوقعات جزئياً"), AND(Main!AZ14="يفي بالتوقعات جزئياً", Main!BA14="يفي بالتوقعات")), "يفي بالتوقعات جزئياً", IF(AND(Main!AZ14="يفي بالتوقعات جزئياً", Main!BA14="يفي بالتوقعات جزئياً"), "يفي بالتوقعات جزئياً", "" )))))))
A15: 79 | B15: 45811.392 | C15: 45811.394 | D15: 840101929@moe.bh | E15: FATEMA ABDULAMEER ABDULLA HASAN | F15: رنى فرحان عوض بني خالد | G15: قسم المواد الاجتماعية | H15: 2024-2025 | J15: الفصل الدراسي الأول | K15: زيارات القيادة العليا للقيادة الوسطى | N15: الزيارة الثانية | O15: يتجاوز التوقعات بكثير | P15: يتجاوز التوقعات بكثير | Q15: يتجاوز التوقعات بكثير | R15: يتجاوز التوقعات بكثير | S15: يتجاوز التوقعات بكثير | T15: يتجاوز التوقعات بكثير | U15: يتجاوز التوقعات بكثير | V15: يتجاوز التوقعات بكثير | W15: يتجاوز التوقعات بكثير | X15: يتجاوز التوقعات بكثير | Y15: يتجاوز التوقعات بكثير | Z15: يتجاوز التوقعات بكثير | AA15: يتجاوز التوقعات بكثير | AB15: يتجاوز التوقعات بكثير | AC15: يتجاوز التوقعات بكثير | AD15: يتجاوز التوقعات بكثير | AE15: يتجاوز التوقعات بكثير | AF15: يتجاوز التوقعات بكثير | AG15: اداء متميز للموقف التعليمي ومتسلسل يحتوي جميع عناصر الدرس الجيد | AH15: . | CK15: =IF(AND(Main!AA15="يتجاوز التوقعات بكثير", Main!AB15="يتجاوز التوقعات بكثير"), "يتجاوز التوقعات بكثير", IF(OR(AND(Main!AA15="يتجاوز التوقعات بكثير", Main!AB15="يتجاوز التوقعات"), AND(Main!AA15="يتجاوز التوقعات", Main!AB15="يتجاوز التوقعات بكثير")), "يتجاوز التوقعات", IF(AND(Main!AA15="يتجاوز التوقعات", Main!AB15="يتجاوز التوقعات"), "يتجاوز التوقعات", IF(OR(AND(Main!AA15="يتجاوز التوقعات", Main!AB15="يفي بالتوقعات"), AND(Main!AA15="يفي بالتوقعات", Main!AB15="يتجاوز التوقعات")), "يفي بالتوقعات", IF(AND(Main!AA15="يفي بالتوقعات", Main!AB15="يفي بالتوقعات"), "يفي بالتوقعات", IF(OR(AND(Main!AA15="يفي بالتوقعات", Main!AB15="يفي بالتوقعات جزئياً"), AND(Main!AA15="يفي بالتوقعات جزئياً", Main!AB15="يفي بالتوقعات")), "يفي بالتوقعات جزئياً", IF(AND(Main!AA15="يفي بالتوقعات جزئياً", Main!AB15="يفي بالتوقعات جزئياً"), "يفي بالتوقعات جزئياً", "" ))))))) -> يتجاوز التوقعات بكثير | CL15: =IF(AND(Main!AZ15="يتجاوز التوقعات بكثير", Main!BA15="يتجاوز التوقعات بكثير"), "يتجاوز التوقعات بكثير", IF(OR(AND(Main!AZ15="يتجاوز التوقعات بكثير", Main!BA15="يتجاوز التوقعات"), AND(Main!AZ15="يتجاوز التوقعات", Main!BA15="يتجاوز التوقعات بكثير")), "يتجاوز التوقعات", IF(AND(Main!AZ15="يتجاوز التوقعات", Main!BA15="يتجاوز التوقعات"), "يتجاوز التوقعات", IF(OR(AND(Main!AZ15="يتجاوز التوقعات", Main!BA15="يفي بالتوقعات"), AND(Main!AZ15="يفي بالتوقعات", Main!BA15="يتجاوز التوقعات")), "يفي بالتوقعات", IF(AND(Main!AZ15="يفي بالتوقعات", Main!BA15="يفي بالتوقعات"), "يفي بالتوقعات", IF(OR(AND(Main!AZ15="يفي بالتوقعات", Main!BA15="يفي بالتوقعات جزئياً"), AND(Main!AZ15="يفي بالتوقعات جزئياً", Main!BA15="يفي بالتوقعات")), "يفي بالتوقعات جزئياً", IF(AND(Main!AZ15="يفي بالتوقعات جزئياً", Main!BA15="يفي بالتوقعات جزئياً"), "يفي بالتوقعات جزئياً", "" )))))))
A16: 80 | B16: 45811.391 | C16: 45811.394 | D16: 841204802@moe.bh | E16: RUQAYAH YOUSIF ABDULLA SHARIF | F16: رقية يوسف عبدا لله شريف | G16: قسم اللغة الانجليزية | H16: 2024-2025 | J16: الفصل الدراسي الأول | K16: زيارات القيادة العليا للقيادة الوسطى | N16: الزيارة الأولى | O16: يتجاوز التوقعات بكثير | P16: يتجاوز التوقعات بكثير | Q16: يتجاوز التوقعات بكثير | R16: يتجاوز التوقعات بكثير | S16: يتجاوز التوقعات بكثير | T16: يتجاوز التوقعات بكثير | U16: يتجاوز التوقعات بكثير | V16: يتجاوز التوقعات بكثير | W16: يتجاوز التوقعات بكثير | X16: يتجاوز التوقعات بكثير | Y16: يتجاوز التوقعات بكثير | Z16: يتجاوز التوقعات بكثير | AA16: يتجاوز التوقعات بكثير | AB16: يتجاوز التوقعات بكثير | AC16: يتجاوز التوقعات بكثير | AD16: يتجاوز التوقعات بكثير | AE16: يتجاوز التوقعات بكثير | AF16: يتجاوز التوقعات بكثير | AG16: 1. تنوع الاستراتيحيات 2. مراعاة الفروق الفردية 3. الاستفادة من نتائج التقويم في دعم الفئات بشكل فعال | AH16: - | CK16: =IF(AND(Main!AA16="يتجاوز التوقعات بكثير", Main!AB16="يتجاوز التوقعات بكثير"), "يتجاوز التوقعات بكثير", IF(OR(AND(Main!AA16="يتجاوز التوقعات بكثير", Main!AB16="يتجاوز التوقعات"), AND(Main!AA16="يتجاوز التوقعات", Main!AB16="يتجاوز التوقعات بكثير")), "يتجاوز التوقعات", IF(AND(Main!AA16="يتجاوز التوقعات", Main!AB16="يتجاوز التوقعات"), "يتجاوز التوقعات", IF(OR(AND(Main!AA16="يتجاوز التوقعات", Main!AB16="يفي بالتوقعات"), AND(Main!AA16="يفي بالتوقعات", Main!AB16="يتجاوز التوقعات")), "يفي بالتوقعات", IF(AND(Main!AA16="يفي بالتوقعات", Main!AB16="يفي بالتوقعات"), "يفي بالتوقعات", IF(OR(AND(Main!AA16="يفي بالتوقعات", Main!AB16="يفي بالتوقعات جزئياً"), AND(Main!AA16="يفي بالتوقعات جزئياً", Main!AB16="يفي بالتوقعات")), "يفي بالتوقعات جزئياً", IF(AND(Main!AA16="يفي بالتوقعات جزئياً", Main!AB16="يفي بالتوقعات جزئياً"), "يفي بالتوقعات جزئياً", "" ))))))) -> يتجاوز التوقعات بكثير | CL16: =IF(AND(Main!AZ16="يتجاوز التوقعات بكثير", Main!BA16="يتجاوز التوقعات بكثير"), "يتجاوز التوقعات بكثير", IF(OR(AND(Main!AZ16="يتجاوز التوقعات بكثير", Main!BA16="يتجاوز التوقعات"), AND(Main!AZ16="يتجاوز التوقعات", Main!BA16="يتجاوز التوقعات بكثير")), "يتجاوز التوقعات", IF(AND(Main!AZ16="يتجاوز التوقعات", Main!BA16="يتجاوز التوقعات"), "يتجاوز التوقعات", IF(OR(AND(Main!AZ16="يتجاوز التوقعات", Main!BA16="يفي بالتوقعات"), AND(Main!AZ16="يفي بالتوقعات", Main!BA16="يتجاوز التوقعات")), "يفي بالتوقعات", IF(AND(Main!AZ16="يفي بالتوقعات", Main!BA16="يفي بالتوقعات"), "يفي بالتوقعات", IF(OR(AND(Main!AZ16="يفي بالتوقعات", Main!BA16="يفي بالتوقعات جزئياً"), AND(Main!AZ16="يفي بالتوقعات جزئياً", Main!BA16="يفي بالتوقعات")), "يفي بالتوقعات جزئياً", IF(AND(Main!AZ16="يفي بالتوقعات جزئياً", Main!BA16="يفي بالتوقعات جزئياً"), "يفي بالتوقعات جزئياً", "" )))))))
A17: 81 | B17: 45811.393 | C17: 45811.395 | D17: 890302057@moe.bh | E17: Afaf Hussain Ahmed Ebrahim Hussain Ahmed Ebrahim | F17: بشرى عبدالكريم يحيي | G17: قسم الحاسب الآلي | H17: 2024-2025 | J17: الفصل الدراسي الأول | K17: زيارات القيادة الوسطى لجميع المعلمات | M17: استمارة الزيارة الصفية | N17: الزيارة الثالثة | O17: يتجاوز التوقعات بكثير | P17: يتجاوز التوقعات بكثير | Q17: يتجاوز التوقعات بكثير | R17: يتجاوز التوقعات | S17: يتجاوز التوقعات بكثير | T17: يتجاوز التوقعات بكثير | U17: يتجاوز التوقعات | V17: يتجاوز التوقعات بكثير | W17: يتجاوز التوقعات بكثير | X17: يتجاوز التوقعات بكثير | Y17: يتجاوز التوقعات بكثير | Z17: يتجاوز التوقعات بكثير | AA17: يتجاوز التوقعات | AB17: يتجاوز التوقعات بكثير | AC17: يتجاوز التوقعات بكثير | AD17: يتجاوز التوقعات بكثير | AE17: يتجاوز التوقعات بكثير | AF17: يتجاوز التوقعات بكثير | AG17: تدريب الطالبات على المهارات بشكل منظم ومبتكر | AH17: - | CK17: =IF(AND(Main!AA17="يتجاوز التوقعات بكثير", Main!AB17="يتجاوز التوقعات بكثير"), "يتجاوز التوقعات بكثير", IF(OR(AND(Main!AA17="يتجاوز التوقعات بكثير", Main!AB17="يتجاوز التوقعات"), AND(Main!AA17="يتجاوز التوقعات", Main!AB17="يتجاوز التوقعات بكثير")), "يتجاوز التوقعات", IF(AND(Main!AA17="يتجاوز التوقعات", Main!AB17="يتجاوز التوقعات"), "يتجاوز التوقعات", IF(OR(AND(Main!AA17="يتجاوز التوقعات", Main!AB17="يفي بالتوقعات"), AND(Main!AA17="يفي بالتوقعات", Main!AB17="يتجاوز التوقعات")), "يفي بالتوقعات", IF(AND(Main!AA17="يفي بالتوقعات", Main!AB17="يفي بالتوقعات"), "يفي بالتوقعات", IF(OR(AND(Main!AA17="يفي بالتوقعات", Main!AB17="يفي بالتوقعات جزئياً"), AND(Main!AA17="يفي بالتوقعات جزئياً", Main!AB17="يفي بالتوقعات")), "يفي بالتوقعات جزئياً", IF(AND(Main!AA17="يفي بالتوقعات جزئياً", Main!AB17="يفي بالتوقعات جزئياً"), "يفي بالتوقعات جزئياً", "" ))))))) -> يتجاوز التوقعات | CL17: =IF(AND(Main!AZ17="يتجاوز التوقعات بكثير", Main!BA17="يتجاوز التوقعات بكثير"), "يتجاوز التوقعات بكثير", IF(OR(AND(Main!AZ17="يتجاوز التوقعات بكثير", Main!BA17="يتجاوز التوقعات"), AND(Main!AZ17="يتجاوز التوقعات", Main!BA17="يتجاوز التوقعات بكثير")), "يتجاوز التوقعات", IF(AND(Main!AZ17="يتجاوز التوقعات", Main!BA17="يتجاوز التوقعات"), "يتجاوز التوقعات", IF(OR(AND(Main!AZ17="يتجاوز التوقعات", Main!BA17="يفي بالتوقعات"), AND(Main!AZ17="يفي بالتوقعات", Main!BA17="يتجاوز التوقعات")), "يفي بالتوقعات", IF(AND(Main!AZ17="يفي بالتوقعات", Main!BA17="يفي بالتوقعات"), "يفي بالتوقعات", IF(OR(AND(Main!AZ17="يفي بالتوقعات", Main!BA17="يفي بالتوقعات جزئياً"), AND(Main!AZ17="يفي بالتوقعات جزئياً", Main!BA17="يفي بالتوقعات")), "يفي بالتوقعات جزئياً", IF(AND(Main!AZ17="يفي بالتوقعات جزئياً", Main!BA17="يفي بالتوقعات جزئياً"), "يفي بالتوقعات جزئياً", "" )))))))
A18: 82 | B18: 45811.394 | C18: 45811.397 | D18: 841204802@moe.bh | E18: RUQAYAH YOUSIF ABDULLA SHARIF | F18: رقية يوسف عبدا لله شريف | G18: قسم اللغة الانجليزية | H18: 2024-2025 | J18: الفصل الدراسي الأول | K18: زيارات القيادة العليا للقيادة الوسطى | N18: الزيارة الثانية | O18: يتجاوز التوقعات بكثير | P18: يتجاوز التوقعات بكثير | Q18: يتجاوز التوقعات بكثير | R18: يتجاوز التوقعات بكثير | S18: يتجاوز التوقعات بكثير | T18: يتجاوز التوقعات بكثير | U18: يتجاوز التوقعات بكثير | V18: يتجاوز التوقعات بكثير | W18: يتجاوز التوقعات بكثير | X18: يتجاوز التوقعات بكثير | Y18: يتجاوز التوقعات بكثير | Z18: يتجاوز التوقعات بكثير | AA18: يتجاوز التوقعات بكثير | AB18: يتجاوز التوقعات بكثير | AC18: يتجاوز التوقعات بكثير | AD18: يتجاوز التوقعات بكثير | AE18: يتجاوز التوقعات بكثير | AF18: يتجاوز التوقعات بكثير | AG18: 1. تنوع اساليب التحفيز عبر بطاقات النسح وملصقات تشجيعية 2. اظهار الطالبات مهاراتهن من خلال إعداد استبانة عن القراءة وعرض نتائجها كنشاط استهلالي بالاضافة اللى اجراء مقابلة بين طالبة وقارئة حول عادات القراءة وعرض مسابقة بعد المقابلة 3. تدريب الطالبات على مهارات اللغة الانجليزية "الاستماع والقراءة و الكتابة والتحدث" في حصة واحدة | AH18: 1. اظهار الدعم الاكاديمي بشكل اوضح بعد نشاط التقييم للطالبات اللاتي اخفقن | CK18: =IF(AND(Main!AA18="يتجاوز التوقعات بكثير", Main!AB18="يتجاوز التوقعات بكثير"), "يتجاوز التوقعات بكثير", IF(OR(AND(Main!AA18="يتجاوز التوقعات بكثير", Main!AB18="يتجاوز التوقعات"), AND(Main!AA18="يتجاوز التوقعات", Main!AB18="يتجاوز التوقعات بكثير")), "يتجاوز التوقعات", IF(AND(Main!AA18="يتجاوز التوقعات", Main!AB18="يتجاوز التوقعات"), "يتجاوز التوقعات", IF(OR(AND(Main!AA18="يتجاوز التوقعات", Main!AB18="يفي بالتوقعات"), AND(Main!AA18="يفي بالتوقعات", Main!AB18="يتجاوز التوقعات")), "يفي بالتوقعات", IF(AND(Main!AA18="يفي بالتوقعات", Main!AB18="يفي بالتوقعات"), "يفي بالتوقعات", IF(OR(AND(Main!AA18="يفي بالتوقعات", Main!AB18="يفي بالتوقعات جزئياً"), AND(Main!AA18="يفي بالتوقعات جزئياً", Main!AB18="يفي بالتوقعات")), "يفي بالتوقعات جزئياً", IF(AND(Main!AA18="يفي بالتوقعات جزئياً", Main!AB18="يفي بالتوقعات جزئياً"), "يفي بالتوقعات جزئياً", "" ))))))) -> يتجاوز التوقعات بكثير | CL18: =IF(AND(Main!AZ18="يتجاوز التوقعات بكثير", Main!BA18="يتجاوز التوقعات بكثير"), "يتجاوز التوقعات بكثير", IF(OR(AND(Main!AZ18="يتجاوز التوقعات بكثير", Main!BA18="يتجاوز التوقعات"), AND(Main!AZ18="يتجاوز التوقعات", Main!BA18="يتجاوز التوقعات بكثير")), "يتجاوز التوقعات", IF(AND(Main!AZ18="يتجاوز التوقعات", Main!BA18="يتجاوز التوقعات"), "يتجاوز التوقعات", IF(OR(AND(Main!AZ18="يتجاوز التوقعات", Main!BA18="يفي بالتوقعات"), AND(Main!AZ18="يفي بالتوقعات", Main!BA18="يتجاوز التوقعات")), "يفي بالتوقعات", IF(AND(Main!AZ18="يفي بالتوقعات", Main!BA18="يفي بالتوقعات"), "يفي بالتوقعات", IF(OR(AND(Main!AZ18="يفي بالتوقعات", Main!BA18="يفي بالتوقعات جزئياً"), AND(Main!AZ18="يفي بالتوقعات جزئياً", Main!BA18="يفي بالتوقعات")), "يفي بالتوقعات جزئياً", IF(AND(Main!AZ18="يفي بالتوقعات جزئياً", Main!BA18="يفي بالتوقعات جزئياً"), "يفي بالتوقعات جزئياً", "" )))))))
A19: 83 | B19: 45811.395 | C19: 45811.398 | D19: 840101929@moe.bh | E19: FATEMA ABDULAMEER ABDULLA HASAN | F19: رنى فرحان عوض بني خالد | G19: قسم المواد الاجتماعية | H19: 2024-2025 | J19: الفصل الدراسي الأول | K19: زيارات القيادة العليا للقيادة الوسطى | N19: الزيارة الثانية | O19: يتجاوز التوقعات بكثير | P19: يتجاوز التوقعات بكثير | Q19: يتجاوز التوقعات بكثير | R19: يتجاوز التوقعات بكثير | S19: يتجاوز التوقعات بكثير | T19: يتجاوز التوقعات بكثير | U19: يتجاوز التوقعات بكثير | V19: يتجاوز التوقعات بكثير | W19: يتجاوز التوقعات بكثير | X19: يتجاوز التوقعات بكثير | Y19: يتجاوز التوقعات بكثير | Z19: يتجاوز التوقعات بكثير | AA19: يتجاوز التوقعات بكثير | AB19: يتجاوز التوقعات بكثير | AC19: يتجاوز التوقعات بكثير | AD19: يتجاوز التوقعات بكثير | AE19: يتجاوز التوقعات بكثير | AF19: يتجاوز التوقعات بكثير | AG19: اداء متميز للموقف التعليمي ومتسلسل يحتوي على جميع عناصر الدرس الجيد | AH19: . | CK19: =IF(AND(Main!AA19="يتجاوز التوقعات بكثير", Main!AB19="يتجاوز التوقعات بكثير"), "يتجاوز التوقعات بكثير", IF(OR(AND(Main!AA19="يتجاوز التوقعات بكثير", Main!AB19="يتجاوز التوقعات"), AND(Main!AA19="يتجاوز التوقعات", Main!AB19="يتجاوز التوقعات بكثير")), "يتجاوز التوقعات", IF(AND(Main!AA19="يتجاوز التوقعات", Main!AB19="يتجاوز التوقعات"), "يتجاوز التوقعات", IF(OR(AND(Main!AA19="يتجاوز التوقعات", Main!AB19="يفي بالتوقعات"), AND(Main!AA19="يفي بالتوقعات", Main!AB19="يتجاوز التوقعات")), "يفي بالتوقعات", IF(AND(Main!AA19="يفي بالتوقعات", Main!AB19="يفي بالتوقعات"), "يفي بالتوقعات", IF(OR(AND(Main!AA19="يفي بالتوقعات", Main!AB19="يفي بالتوقعات جزئياً"), AND(Main!AA19="يفي بالتوقعات جزئياً", Main!AB19="يفي بالتوقعات")), "يفي بالتوقعات جزئياً", IF(AND(Main!AA19="يفي بالتوقعات جزئياً", Main!AB19="يفي بالتوقعات جزئياً"), "يفي بالتوقعات جزئياً", "" ))))))) -> يتجاوز التوقعات بكثير | CL19: =IF(AND(Main!AZ19="يتجاوز التوقعات بكثير", Main!BA19="يتجاوز التوقعات بكثير"), "يتجاوز التوقعات بكثير", IF(OR(AND(Main!AZ19="يتجاوز التوقعات بكثير", Main!BA19="يتجاوز التوقعات"), AND(Main!AZ19="يتجاوز التوقعات", Main!BA19="يتجاوز التوقعات بكثير")), "يتجاوز التوقعات", IF(AND(Main!AZ19="يتجاوز التوقعات", Main!BA19="يتجاوز التوقعات"), "يتجاوز التوقعات", IF(OR(AND(Main!AZ19="يتجاوز التوقعات", Main!BA19="يفي بالتوقعات"), AND(Main!AZ19="يفي بالتوقعات", Main!BA19="يتجاوز التوقعات")), "يفي بالتوقعات", IF(AND(Main!AZ19="يفي بالتوقعات", Main!BA19="يفي بالتوقعات"), "يفي بالتوقعات", IF(OR(AND(Main!AZ19="يفي بالتوقعات", Main!BA19="يفي بالتوقعات جزئياً"), AND(Main!AZ19="يفي بالتوقعات جزئياً", Main!BA19="يفي بالتوقعات")), "يفي بالتوقعات جزئياً", IF(AND(Main!AZ19="يفي بالتوقعات جزئياً", Main!BA19="يفي بالتوقعات جزئياً"), "يفي بالتوقعات جزئياً", "" )))))))
A20: 85 | B20: 45811.398 | C20: 45811.4 | D20: 841204802@moe.bh | E20: RUQAYAH YOUSIF ABDULLA SHARIF | F20: رقية يوسف عبدا لله شريف | G20: قسم اللغة الانجليزية | H20: 2024-2025 | J20: الفصل الدراسي الأول | K20: زيارات القيادة العليا للقيادة الوسطى | N20: الزيارة الثالثة | O20: يتجاوز التوقعات بكثير | P20: يتجاوز التوقعات بكثير | Q20: يتجاوز التوقعات بكثير | R20: يتجاوز التوقعات بكثير | S20: يتجاوز التوقعات بكثير | T20: يتجاوز التوقعات بكثير | U20: يتجاوز التوقعات بكثير | V20: يتجاوز التوقعات بكثير | W20: يتجاوز التوقعات بكثير | X20: يتجاوز التوقعات بكثير | Y20: يتجاوز التوقعات بكثير | Z20: يتجاوز التوقعات بكثير | AA20: يتجاوز التوقعات بكثير | AB20: يتجاوز التوقعات بكثير | AC20: يتجاوز التوقعات بكثير | AD20: يتجاوز التوقعات بكثير | AE20: يتجاوز التوقعات بكثير | AF20: يتجاوز التوقعات بكثير | AG20: 1. تنوع وتمايز الانشطة المقدمة 2. وضوح فاعل للادوار القيادية طوال الحصة 3. تنوع وفعالية استراتيجيات التعلم | AH20: - | CK20: =IF(AND(Main!AA20="يتجاوز التوقعات بكثير", Main!AB20="يتجاوز التوقعات بكثير"), "يتجاوز التوقعات بكثير", IF(OR(AND(Main!AA20="يتجاوز التوقعات بكثير", Main!AB20="يتجاوز التوقعات"), AND(Main!AA20="يتجاوز التوقعات", Main!AB20="يتجاوز التوقعات بكثير")), "يتجاوز التوقعات", IF(AND(Main!AA20="يتجاوز التوقعات", Main!AB20="يتجاوز التوقعات"), "يتجاوز التوقعات", IF(OR(AND(Main!AA20="يتجاوز التوقعات", Main!AB20="يفي بالتوقعات"), AND(Main!AA20="يفي بالتوقعات", Main!AB20="يتجاوز التوقعات")), "يفي بالتوقعات", IF(AND(Main!AA20="يفي بالتوقعات", Main!AB20="يفي بالتوقعات"), "يفي بالتوقعات", IF(OR(AND(Main!AA20="يفي بالتوقعات", Main!AB20="يفي بالتوقعات جزئياً"), AND(Main!AA20="يفي بالتوقعات جزئياً", Main!AB20="يفي بالتوقعات")), "يفي بالتوقعات جزئياً", IF(AND(Main!AA20="يفي بالتوقعات جزئياً", Main!AB20="يفي بالتوقعات جزئياً"), "يفي بالتوقعات جزئياً", "" ))))))) -> يتجاوز التوقعات بكثير | CL20: =IF(AND(Main!AZ20="يتجاوز التوقعات بكثير", Main!BA20="يتجاوز التوقعات بكثير"), "يتجاوز التوقعات بكثير", IF(OR(AND(Main!AZ20="يتجاوز التوقعات بكثير", Main!BA20="يتجاوز التوقعات"), AND(Main!AZ20="يتجاوز التوقعات", Main!BA20="يتجاوز التوقعات بكثير")), "يتجاوز التوقعات", IF(AND(Main!AZ20="يتجاوز التوقعات", Main!BA20="يتجاوز التوقعات"), "يتجاوز التوقعات", IF(OR(AND(Main!AZ20="يتجاوز التوقعات", Main!BA20="يفي بالتوقعات"), AND(Main!AZ20="يفي بالتوقعات", Main!BA20="يتجاوز التوقعات")), "يفي بالتوقعات", IF(AND(Main!AZ20="يفي بالتوقعات", Main!BA20="يفي بالتوقعات"), "يفي بالتوقعات", IF(OR(AND(Main!AZ20="يفي بالتوقعات", Main!BA20="يفي بالتوقعات جزئياً"), AND(Main!AZ20="يفي بالتوقعات جزئياً", Main!BA20="يفي بالتوقعات")), "يفي بالتوقعات جزئياً", IF(AND(Main!AZ20="يفي بالتوقعات جزئياً", Main!BA20="يفي بالتوقعات جزئياً"), "يفي بالتوقعات جزئياً", "" )))))))
A21: 86 | B21: 45811.4 | C21: 45811.401 | D21: 840101929@moe.bh | E21: FATEMA ABDULAMEER ABDULLA HASAN | F21: علياء محمد احمد فردان | G21: قسم المواد الاجتماعية | H21: 2024-2025 | J21: الفصل الدراسي الأول | K21: زيارات القيادة الوسطى لجميع المعلمات | M21: استمارة الزيارة الصفية | N21: الزيارة الثانية | O21: يتجاوز التوقعات بكثير | P21: يتجاوز التوقعات بكثير | Q21: يتجاوز التوقعات بكثير | R21: يتجاوز التوقعات بكثير | S21: يتجاوز التوقعات بكثير | T21: يتجاوز التوقعات بكثير | U21: يتجاوز التوقعات بكثير | V21: يتجاوز التوقعات بكثير | W21: يتجاوز التوقعات بكثير | X21: يتجاوز التوقعات بكثير | Y21: يتجاوز التوقعات بكثير | Z21: يتجاوز التوقعات بكثير | AA21: يتجاوز التوقعات بكثير | AB21: يتجاوز التوقعات بكثير | AC21: يتجاوز التوقعات بكثير | AD21: يتجاوز التوقعات بكثير | AE21: يتجاوز التوقعات بكثير | AF21: يتجاوز التوقعات بكثير | AG21: اداء متميز للموقف التعليمي ومتسلسل ويحتوي على جميع عناصر الدرس الجيد | AH21: . | CK21: =IF(AND(Main!AA21="يتجاوز التوقعات بكثير", Main!AB21="يتجاوز التوقعات بكثير"), "يتجاوز التوقعات بكثير", IF(OR(AND(Main!AA21="يتجاوز التوقعات بكثير", Main!AB21="يتجاوز التوقعات"), AND(Main!AA21="يتجاوز التوقعات", Main!AB21="يتجاوز التوقعات بكثير")), "يتجاوز التوقعات", IF(AND(Main!AA21="يتجاوز التوقعات", Main!AB21="يتجاوز التوقعات"), "يتجاوز التوقعات", IF(OR(AND(Main!AA21="يتجاوز التوقعات", Main!AB21="يفي بالتوقعات"), AND(Main!AA21="يفي بالتوقعات", Main!AB21="يتجاوز التوقعات")), "يفي بالتوقعات", IF(AND(Main!AA21="يفي بالتوقعات", Main!AB21="يفي بالتوقعات"), "يفي بالتوقعات", IF(OR(AND(Main!AA21="يفي بالتوقعات", Main!AB21="يفي بالتوقعات جزئياً"), AND(Main!AA21="يفي بالتوقعات جزئياً", Main!AB21="يفي بالتوقعات")), "يفي بالتوقعات جزئياً", IF(AND(Main!AA21="يفي بالتوقعات جزئياً", Main!AB21="يفي بالتوقعات جزئياً"), "يفي بالتوقعات جزئياً", "" ))))))) -> يتجاوز التوقعات بكثير | CL21: =IF(AND(Main!AZ21="يتجاوز التوقعات بكثير", Main!BA21="يتجاوز التوقعات بكثير"), "يتجاوز التوقعات بكثير", IF(OR(AND(Main!AZ21="يتجاوز التوقعات بكثير", Main!BA21="يتجاوز التوقعات"), AND(Main!AZ21="يتجاوز التوقعات", Main!BA21="يتجاوز التوقعات بكثير")), "يتجاوز التوقعات", IF(AND(Main!AZ21="يتجاوز التوقعات", Main!BA21="يتجاوز التوقعات"), "يتجاوز التوقعات", IF(OR(AND(Main!AZ21="يتجاوز التوقعات", Main!BA21="يفي بالتوقعات"), AND(Main!AZ21="يفي بالتوقعات", Main!BA21="يتجاوز التوقعات")), "يفي بالتوقعات", IF(AND(Main!AZ21="يفي بالتوقعات", Main!BA21="يفي بالتوقعات"), "يفي بالتوقعات", IF(OR(AND(Main!AZ21="يفي بالتوقعات", Main!BA21="يفي بالتوقعات جزئياً"), AND(Main!AZ21="يفي بالتوقعات جزئياً", Main!BA21="يفي بالتوقعات")), "يفي بالتوقعات جزئياً", IF(AND(Main!AZ21="يفي بالتوقعات جزئياً", Main!BA21="يفي بالتوقعات جزئياً"), "يفي بالتوقعات جزئياً", "" )))))))
